<?xml  version="1.0"?>
<robot name ="objects"> 
    <!-- Author: Chengjin Wang; e-mail:2210991@tongji.edu.cn. The urdf file was develped in tongji university.-->

    <!--create  color params-->
    <material name ="LightGrey">
        <color rgba="0.7 0.7 0.7 1.0"/>
    </material>

    <material name ="White">
        <color rgba="1 1 1 1.0"/>
    </material>

    <material name ="Green">
        <color rgba="0.1 0. 1.0 1.0"/>
    </material>

    <material name ="Yellow">
        <color rgba="1. 1. 0. 1.0"/>
    </material>

    <material name ="Orange">
        <color rgba="1. 0.38 0. 1.0"/>
    </material>

    <material name ="Blue">
        <color rgba="0.69 0.87 0.9 1.0"/>
    </material>

    <mass name ="table_mass">
        <mass value="1.0"/>
    </mass>

    <mass name ="cylander_mass">
        <mass value="2.0"/>
    </mass>



    <link  name ="World"/>

    <joint name="cylinder1_to_world" type="floating">
        <parent link="World"/>
        <child link="cylinder1"/>
        <origin xyz="0. 0. 0." rpy="0.0 0.0 0.0"/>
    </joint>

    <link name = "cylinder1">
        <contact>
            <lateral_friction value="0.05"/>
            <rolling_friction value="0.0"/>
            <contact_erp value="1.0"/>
        </contact>
        <visual>
            <origin  xyz="0.0 0.0 0.0" rpy="0.0 0.0 0.0"/>
            <geometry>
                <mesh filename = "meshes/cylinder_2.dae"/>
            </geometry >
            <material name ="Blue"/>
        </visual>
        <collision>
            <origin xyz="0.0 0.0 0.0" rpy="0.0 0.0 0.0"/>
            <geometry>
                <mesh filename ="meshes/cylinder_2.dae"/>
            </geometry>
        </collision>
        <inertial>
            <mass value = "0.5"/>
            <inertia ixx="1" ixy="0.0" ixz="0.0" iyy="1" iyz="0.0" izz="1"/>
        </inertial>
    </link>
</robot>
